from fastapi import FastAPI, HTTPException
from typing import Dict

app = FastAPI()

# Изначальный словарь пользователей
users: Dict[str, str] = {'1': 'Имя: Example, возраст: 18'}


@app.get("/users", response_model=Dict[str, str])
async def get_users() -> Dict[str, str]:
    """Возвращает словарь пользователей."""
    return users


@app.post("/user/{username}/{age}", response_model=str)
async def create_user(username: str, age: int) -> str:
    """Добавляет нового пользователя в словарь."""
    new_user_id = str(max(map(int, users.keys()), default=0) + 1)
    users[new_user_id] = f"Имя: {username}, возраст: {age}"
    return f"User {new_user_id} is registered"


@app.put("/user/{user_id}/{username}/{age}", response_model=str)
async def update_user(user_id: str, username: str, age: int) -> str:
    """Обновляет существующего пользователя по указанному ID."""
    if user_id not in users:
        raise HTTPException(status_code=404, detail="User not found")
    users[user_id] = f"Имя: {username}, возраст: {age}"
    return f"User {user_id} has been updated"


@app.delete("/user/{user_id}", response_model=str)
async def delete_user(user_id: str) -> str:
    """Удаляет пользователя по указанному ID."""
    if user_id not in users:
        raise HTTPException(status_code=404, detail="User not found")
    del users[user_id]
    return f"User {user_id} has been deleted"

# Запуск приложения
# uvicorn main:app --reload